<?xml version="1.0"?>

<robot xmlns:xacro="http://ros.org/wiki/xacro" name="smb_wheel">
	 
	  <!-- Wheel Properties -->
	<xacro:property name="wheel_length" value="0.10414" />
	<xacro:property name="wheel_radius" value="0.149225" />
	<xacro:property name="wheel_mass" value="4.18" />


	<xacro:macro name="wheel_inertia" params="m r h">
		<inertia ixx="${m*(3*r*r+h*h)/12}" ixy="0" ixz="0"
				iyy="${m*r*r/2}" iyz="0"
				izz="${m*(3*r*r+h*h)/12}" />
  	</xacro:macro>

	<xacro:macro name="smb_wheel" params="wheel_prefix *joint_pose">
		<link name="${wheel_prefix}_wheel_link">
			<inertial>
				<mass value="${wheel_mass}"/>
				<origin xyz="0 0 0" rpy="0 1.5707 1.5707"/>
				<xacro:wheel_inertia m="${wheel_mass}" r="${wheel_radius}" h="${wheel_length}" />
			</inertial>
			<visual>
				<origin xyz="0 0 0" rpy="0 0 ${M_PI}" />
				<geometry>
					<mesh filename="package://smb_description/meshes/wheel.dae" />
				</geometry>
			</visual>
			<collision>
				<origin xyz="0 0 0" rpy="${M_PI/2} 0 0"/>
				<geometry>
					<cylinder length="${wheel_length}" radius="${wheel_radius}" />
				</geometry>
			</collision>
		</link>

		<gazebo reference="${wheel_prefix}_wheel_link">
			<mu1 value="0.9"/>
			<mu2 value="0.5"/>
			<kp value="10000000.0" />
			<kd value="10.0" />
			<fdir1 value="1 0 0"/>
		</gazebo>

		<joint name="${wheel_prefix}_wheel" type="continuous">
			<parent link="base_link"/>
			<child link="${wheel_prefix}_wheel_link"/>
			<xacro:insert_block name="joint_pose"/>
			<axis xyz="0 1 0" rpy="0 0 0" />
		</joint>

		<transmission name="${wheel_prefix}_wheel_trans" type="SimpleTransmission">
			<type>transmission_interface/SimpleTransmission</type>
			<actuator name="${wheel_prefix}_wheel_motor">
				<mechanicalReduction>1</mechanicalReduction>
			</actuator>
			<joint name="${wheel_prefix}_wheel">
				<hardwareInterface>hardware_interface/VelocityJointInterface</hardwareInterface>
			</joint>
		</transmission>

	</xacro:macro>
</robot>
